In Rust, you can propagate errors up to the caller by returning a `Result` type from your function. The `Result` type is an enum that has two variants: `Ok`, which indicates success and contains a value, and `Err`, which indicates an error and contains an error value.

Here's an example of a function that returns a `Result`:

```rust
fn might_fail() -> Result<(), &'static str> {
   // Some code here...

   if something_went_wrong {
       Err("Something went wrong")
   } else {
       Ok(())
   }
}
```

In this function, if something goes wrong, we return `Err` with a string that describes the error. If everything goes well, we return `Ok` with an empty tuple `()`.

You can then call this function and handle the error using a `match` statement or the `?` operator:

```rust
match might_fail() {
   Ok(_) => println!("Everything went well"),
   Err(e) => println!("An error occurred: {}", e),
}
```

Or using the `?` operator:

```rust
fn main() -> Result<(), &'static str> {
   might_fail()?;
   println!("Everything went well");
   Ok(())
}
```

In this example, if `might_fail` returns an `Err`, the `?` operator will immediately return that error from the `main` function. If `might_fail` returns `Ok`, the `?` operator will do nothing and the program will continue to execute.

This is how you can propagate errors up to the caller in Rust. By returning a `Result` from your functions, you allow the caller to decide how to handle the error.


  --------------------------------------------------------------------------------------------------

  Propagating errors up to the caller is a crucial aspect of error handling in Rust. It ensures that errors are not silently ignored and that the caller is informed about any issues that occur during the execution of a function. There are two primary methods for propagating errors up to the caller in Rust:

1. **Returning the `Result` enum:** This is the most common approach for propagating errors. When a function encounters an error, it returns an `Err` variant of the `Result` enum, indicating the specific error that occurred. The caller can then handle the error appropriately.

2. **Using the `?` operator:** The `?` operator is a concise way to handle errors when using the `Result` enum. It allows you to directly unwrap the `Ok` variant of the `Result` and return the contained value. However, if the `Result` is an `Err`, the `?` operator will automatically propagate the error by returning from the current function.

Here's an example of propagating errors using the `Result` enum:

```rust
fn read_file(filename: &str) -> Result<String, std::io::Error> {
    let mut file = File::open(filename)?;
    let mut contents = String::new();
    file.read_to_string(&mut contents)?;
    Ok(contents)
}

fn main() {
    let contents = read_file("my_file.txt").unwrap_or_else(|err| {
        println!("Error reading file: {}", err);
        "".to_string()
    });

    println!("File contents: {}", contents);
}
```

In this example, the `read_file` function returns a `Result` type. If the file is read successfully, the `Ok` variant is returned with the file contents. However, if an error occurs, the `Err` variant is returned with the corresponding error message. The `main` function handles the error by calling `unwrap_or_else`, which provides a fallback value in case of an error.

Alternatively, you can use the `?` operator to propagate errors:

```rust
fn read_file(filename: &str) -> Result<String, std::io::Error> {
    let mut file = File::open(filename)?;
    let mut contents = String::new();
    file.read_to_string(&mut contents)?;
    Ok(contents)
}

fn main() {
    let contents = read_file("my_file.txt")?;
    println!("File contents: {}", contents);
}
```

In this example, the `?` operator directly unwraps the `Ok` variant and returns the file contents. If an error occurs, the `?` operator automatically propagates the error by returning from the `read_file` function. This approach is more concise and avoids the need for explicit error handling in the caller.

Both methods effectively propagate errors up to the caller, ensuring that errors are not silently ignored and that the program can handle them appropriately.



-----------------------------------------------------------------------------------------------------
In Rust, you can propagate errors up to the caller using the `Result` type and the `?` operator. Here's a simple example:

```rust
use std::fs::File;
use std::io::{self, Read};

// Function that reads the content of a file and returns a Result with the content.
fn read_file_content(file_path: &str) -> Result<String, io::Error> {
    let mut file = File::open(file_path)?;

    let mut content = String::new();
    file.read_to_string(&mut content)?;

    Ok(content)
}

// Function that calls read_file_content and propagates the error to its caller.
fn process_file(file_path: &str) -> Result<(), io::Error> {
    let content = read_file_content(file_path)?;

    // Process the content here

    Ok(())
}

// Main function that calls process_file and handles errors.
fn main() {
    let file_path = "example.txt";

    match process_file(file_path) {
        Ok(_) => println!("File processed successfully."),
        Err(err) => eprintln!("Error: {}", err),
    }
}
```

In this example:

1. The `read_file_content` function reads the content of a file and returns a `Result<String, io::Error>`. It uses the `?` operator to propagate errors.

2. The `process_file` function calls `read_file_content` and also uses the `?` operator to propagate any errors up to its caller.

3. The `main` function calls `process_file` and pattern matches on the result to handle success or error cases.

By using the `Result` type and the `?` operator, you can easily propagate errors up the call stack. The `main` function is often a good place to handle top-level errors, and you can choose to display, log, or handle errors in a way that makes sense for your application.


-----------------------------------------------------------------------------------------------------------------------------------------






  
